Workbook

Sheet Order sheet
A1: 🐰EASTER EGGS ORDERS - 2026 🐰 | I1: Profit | J1: =(SUM(Easter[Total Payment])-'Production Sheet'!$E$38) -> 49474.983
Q2: =SUMIF('Order sheet'!$J$6:$J$106,"
A3: Total Sales 💵 | C3: Total Quantity 📦 | F3: Total Customers | I3: Profit % | J3: =($J$1/SUM(Easter[Total Payment])) -> 0.56975854
A4: =SUBTOTAL(109,Easter[Total Payment]) -> 15240 | C4: =SUBTOTAL(109,Easter[[Quantity ]]) -> 255 | F4: {=COUNTA(_xlfn.UNIQUE(_xlfn._xlws.FILTER(Easter[Name],Easter[Name]<>"")))} -> 94
A5: Name | B5: Product Name | C5: Quantity | D5: Price (Per Unit ₹) | E5: Total Payment | F5: Delivery Date | G5: Order status | H5: Payment | I5: Payment Reciever | J5: Advance paid | K5: Extra
A6: Aaron Arul | B6: Almond Crunch Dark Medium | C6: 1 | D6: =IFERROR(VLOOKUP(Easter[[#This Row],[Product Name]],'Lookup sheet'!$A$1:$D$31,4,FALSE),"") -> 60 | E6: =IFERROR(Easter[[#This Row],[Price (Per Unit ₹)]]*Easter[[#This Row],[Quantity ]],"") -> 60 | F6: 46116 | G6: 🚚 Delivered | H6: ✅ Paid in Full | I6: Anna | J6: UPI Anna
A7: Aaron Arul | B7: Bunny Pop Milk | C7: 2 | D7: =IFERROR(VLOOKUP(Easter[[#This Row],[Product Name]],'Lookup sheet'!$A$1:$D$31,4,FALSE),"") -> 40 | E7: =IFERROR(Easter[[#This Row],[Price (Per Unit ₹)]]*Easter[[#This Row],[Quantity ]],"") -> 80 | F7: 46116 | G7: 🚚 Delivered | H7: ✅ Paid in Full | I7: Anna | J7: UPI Anna
A8: Aaron Arul | B8: Rum Drop Medium | C8: 1 | D8: =IFERROR(VLOOKUP(Easter[[#This Row],[Product Name]],'Lookup sheet'!$A$1:$D$31,4,FALSE),"") -> 55 | E8: =IFERROR(Easter[[#This Row],[Price (Per Unit ₹)]]*Easter[[#This Row],[Quantity ]],"") -> 55 | F8: 46116 | G8: 🚚 Delivered | H8: ✅ Paid in Full | I8: Anna | J8: UPI Anna
A9: Adrian | B9: Blueberry Bliss Medium | C9: 1 | D9: =IFERROR(VLOOKUP(Easter[[#This Row],[Product Name]],'Lookup sheet'!$A$1:$D$31,4,FALSE),"") -> 65 | E9: 65 | F9: 46116 | G9: 🚚 Delivered | H9: ✅ Paid in Full | I9: Anna | J9: UPI Anna
A10: Adrian | B10: Cookie and Dreams Medium | C10: 4 | D10: =IFERROR(VLOOKUP(Easter[[#This Row],[Product Name]],'Lookup sheet'!$A$1:$D$31,4,FALSE),"") -> 60 | E10: =IFERROR(Easter[[#This Row],[Price (Per Unit ₹)]]*Easter[[#This Row],[Quantity ]],"") -> 240 | F10: 46116 | G10: 🚚 Delivered | H10: ✅ Paid in Full | I10: Anna | J10: UPI Anna
A11: Adrian | B11: Rum Drop Medium | C11: 1 | D11: =IFERROR(VLOOKUP(Easter[[#This Row],[Product Name]],'Lookup sheet'!$A$1:$D$31,4,FALSE),"") -> 55 | E11: =IFERROR(Easter[[#This Row],[Price (Per Unit ₹)]]*Easter[[#This Row],[Quantity ]],"") -> 55 | F11: 46116 | G11: 🚚 Delivered | H11: ✅ Paid in Full | I11: Anna | J11: UPI Anna
A12: Agnelo | B12: Almond Crunch Milk Medium | C12: 2 | D12: =IFERROR(VLOOKUP(Easter[[#This Row],[Product Name]],'Lookup sheet'!$A$1:$D$31,4,FALSE),"") -> 60 | E12: =IFERROR(Easter[[#This Row],[Price (Per Unit ₹)]]*Easter[[#This Row],[Quantity ]],"") -> 120 | F12: 46116 | G12: 🚚 Delivered | H12: ✅ Paid in Full | I12: Anna | J12: UPI Anna
A13: Agnelo | B13: Blueberry Bliss Medium | C13: 2 | D13: =IFERROR(VLOOKUP(Easter[[#This Row],[Product Name]],'Lookup sheet'!$A$1:$D$31,4,FALSE),"") -> 65 | E13: =IFERROR(Easter[[#This Row],[Price (Per Unit ₹)]]*Easter[[#This Row],[Quantity ]],"") -> 130 | F13: 46116 | G13: 🚚 Delivered | H13: ✅ Paid in Full | I13: Anna | J13: UPI Anna
A14: Agnelo | B14: Cookie and Dreams Medium | C14: 2 | D14: =IFERROR(VLOOKUP(Easter[[#This Row],[Product Name]],'Lookup sheet'!$A$1:$D$31,4,FALSE),"") -> 60 | E14: =IFERROR(Easter[[#This Row],[Price (Per Unit ₹)]]*Easter[[#This Row],[Quantity ]],"") -> 120 | F14: 46116 | G14: 🚚 Delivered | H14: ✅ Paid in Full | I14: Anna | J14: UPI Anna
A15: Agnelo | B15: Mocha Pop Medium | C15: 2 | D15: =IFERROR(VLOOKUP(Easter[[#This Row],[Product Name]],'Lookup sheet'!$A$1:$D$31,4,FALSE),"") -> 55 | E15: =IFERROR(Easter[[#This Row],[Price (Per Unit ₹)]]*Easter[[#This Row],[Quantity ]],"") -> 110 | F15: 46116 | G15: 🚚 Delivered | H15: ✅ Paid in Full | I15: Anna | J15: UPI Anna
A16: Agnelo | B16: Rum Drop Medium | C16: 2 | D16: =IFERROR(VLOOKUP(Easter[[#This Row],[Product Name]],'Lookup sheet'!$A$1:$D$31,4,FALSE),"") -> 55 | E16: =IFERROR(Easter[[#This Row],[Price (Per Unit ₹)]]*Easter[[#This Row],[Quantity ]],"") -> 110 | F16: 46116 | G16: 🚚 Delivered | H16: ✅ Paid in Full | I16: Anna | J16: UPI Anna
A17: Alam Bhaiya | B17: Almond Crunch Milk Mini | C17: 4 | D17: =IFERROR(VLOOKUP(Easter[[#This Row],[Product Name]],'Lookup sheet'!$A$1:$D$31,4,FALSE),"") -> 25 | E17: =IFERROR(Easter[[#This Row],[Price (Per Unit ₹)]]*Easter[[#This Row],[Quantity ]],"") -> 100 | F17: 46117 | G17: 🚚 Delivered | H17: ✅ Paid in Full | I17: Anna | J17: UPI Anna
A18: Alena | B18: Mini Egglet Basket | C18: 1 | D18: =IFERROR(VLOOKUP(Easter[[#This Row],[Product Name]],'Lookup sheet'!$A$1:$D$31,4,FALSE),"") -> 150 | E18: =IFERROR(Easter[[#This Row],[Price (Per Unit ₹)]]*Easter[[#This Row],[Quantity ]],"") -> 150 | F18: 46115 | G18: 🚚 Delivered | H18: ✅ Paid in Full | I18: Anna | J18: Cash
A19: Alena | B19: Party Popper | C19: 1 | D19: =IFERROR(VLOOKUP(Easter[[#This Row],[Product Name]],'Lookup sheet'!$A$1:$D$31,4,FALSE),"") -> 100 | E19: =IFERROR(Easter[[#This Row],[Price (Per Unit ₹)]]*Easter[[#This Row],[Quantity ]],"") -> 100 | F19: 46115 | G19: 🚚 Delivered | H19: ✅ Paid in Full | I19: Anna | J19: Cash
A20: Aletta | B20: Almond Crunch Dark Mini | C20: 7 | D20: =IFERROR(VLOOKUP(Easter[[#This Row],[Product Name]],'Lookup sheet'!$A$1:$D$31,4,FALSE),"") -> 25 | E20: =IFERROR(Easter[[#This Row],[Price (Per Unit ₹)]]*Easter[[#This Row],[Quantity ]],"") -> 175 | F20: 46116 | G20: 🚚 Delivered | H20: ✅ Paid in Full | I20: Anna | J20: Cash
A21: Aletta | B21: Almond Crunch Milk Mini | C21: 7 | D21: =IFERROR(VLOOKUP(Easter[[#This Row],[Product Name]],'Lookup sheet'!$A$1:$D$31,4,FALSE),"") -> 25 | E21: =IFERROR(Easter[[#This Row],[Price (Per Unit ₹)]]*Easter[[#This Row],[Quantity ]],"") -> 175 | F21: 46116 | G21: 🚚 Delivered | H21: ✅ Paid in Full | I21: Anna | J21: Cash
... A72: Claudie | B72: Rum Drop Medium | C72: 8 | D72: =IFERROR(VLOOKUP(Easter[[#This Row],[Product Name]],'Lookup sheet'!$A$1:$D$31,4,FALSE),"") -> 55 | E72: =IFERROR(Easter[[#This Row],[Price (Per Unit ₹)]]*Easter[[#This Row],[Quantity ]],"") -> 440 | F72: 46118 | G72: 🚚 Delivered | H72: ✅ Paid in Full | I72: Sarah | J72: UPI Sarah
A73: Crystal | B73: Almond Crunch Dark Medium | C73: 2 | D73: =IFERROR(VLOOKUP(Easter[[#This Row],[Product Name]],'Lookup sheet'!$A$1:$D$31,4,FALSE),"") -> 60 | E73: =IFERROR(Easter[[#This Row],[Price (Per Unit ₹)]]*Easter[[#This Row],[Quantity ]],"") -> 120 | F73: 46114 | G73: 🚚 Delivered | H73: ✅ Paid in Full | I73: Sarah | J73: UPI Sarah | K73: add 15
A74: Crystal | B74: Almond Crunch Dark Mini | C74: 10 | D74: =IFERROR(VLOOKUP(Easter[[#This Row],[Product Name]],'Lookup sheet'!$A$1:$D$31,4,FALSE),"") -> 25 | E74: =IFERROR(Easter[[#This Row],[Price (Per Unit ₹)]]*Easter[[#This Row],[Quantity ]],"") -> 250 | F74: 46114 | G74: 🚚 Delivered | H74: ✅ Paid in Full | I74: Sarah | J74: UPI Sarah
A75: Crystal | B75: Bold & Plain Milk Large | C75: 5 | D75: =IFERROR(VLOOKUP(Easter[[#This Row],[Product Name]],'Lookup sheet'!$A$1:$D$31,4,FALSE),"") -> 110 | E75: =IFERROR(Easter[[#This Row],[Price (Per Unit ₹)]]*Easter[[#This Row],[Quantity ]],"") -> 550 | F75: 46114 | G75: 🚚 Delivered | H75: ✅ Paid in Full | I75: Sarah | J75: UPI Sarah
A76: Crystal | B76: Cookie and Dreams Medium | C76: 9 | D76: =IFERROR(VLOOKUP(Easter[[#This Row],[Product Name]],'Lookup sheet'!$A$1:$D$31,4,FALSE),"") -> 60 | E76: =IFERROR(Easter[[#This Row],[Price (Per Unit ₹)]]*Easter[[#This Row],[Quantity ]],"") -> 540 | F76: 46114 | G76: 🚚 Delivered | H76: ✅ Paid in Full | I76: Sarah | J76: UPI Sarah
A77: Crystal | B77: Cookie and Dreams Mini | C77: 5 | D77: =IFERROR(VLOOKUP(Easter[[#This Row],[Product Name]],'Lookup sheet'!$A$1:$D$31,4,FALSE),"") -> 25 | E77: =IFERROR(Easter[[#This Row],[Price (Per Unit ₹)]]*Easter[[#This Row],[Quantity ]],"") -> 125 | F77: 46114 | G77: 🚚 Delivered | H77: ✅ Paid in Full | I77: Sarah | J77: UPI Sarah
A78: Crystal | B78: Mini Egglet Basket | C78: 2 | D78: =IFERROR(VLOOKUP(Easter[[#This Row],[Product Name]],'Lookup sheet'!$A$1:$D$31,4,FALSE),"") -> 150 | E78: =IFERROR(Easter[[#This Row],[Price (Per Unit ₹)]]*Easter[[#This Row],[Quantity ]],"") -> 300 | F78: 46114 | G78: 🚚 Delivered | H78: ✅ Paid in Full | I78: Sarah | J78: UPI Sarah
A79: Crystal | B79: Mocha Pop Large | C79: 1 | D79: =IFERROR(VLOOKUP(Easter[[#This Row],[Product Name]],'Lookup sheet'!$A$1:$D$31,4,FALSE),"") -> 130 | E79: =IFERROR(Easter[[#This Row],[Price (Per Unit ₹)]]*Easter[[#This Row],[Quantity ]],"") -> 130 | F79: 46114 | G79: 🚚 Delivered | H79: ✅ Paid in Full | I79: Sarah | J79: UPI Sarah
A80: Crystal | B80: Plain Dark Mini | C80: 2 | D80: =IFERROR(VLOOKUP(Easter[[#This Row],[Product Name]],'Lookup sheet'!$A$1:$D$31,4,FALSE),"") -> 20 | E80: =IFERROR(Easter[[#This Row],[Price (Per Unit ₹)]]*Easter[[#This Row],[Quantity ]],"") -> 40 | F80: 46114 | G80: 🚚 Delivered | H80: ✅ Paid in Full | I80: Sarah | J80: UPI Sarah
A81: Crystal | B81: Plain Milk Medium | C81: 5 | D81: =IFERROR(VLOOKUP(Easter[[#This Row],[Product Name]],'Lookup sheet'!$A$1:$D$31,4,FALSE),"") -> 50 | E81: =IFERROR(Easter[[#This Row],[Price (Per Unit ₹)]]*Easter[[#This Row],[Quantity ]],"") -> 250 | F81: 46114 | G81: 🚚 Delivered | H81: ✅ Paid in Full | I81: Sarah | J81: UPI Sarah
A82: Crystal | B82: Plain Milk Medium | C82: 6 | D82: =IFERROR(VLOOKUP(Easter[[#This Row],[Product Name]],'Lookup sheet'!$A$1:$D$31,4,FALSE),"") -> 50 | E82: =IFERROR(Easter[[#This Row],[Price (Per Unit ₹)]]*Easter[[#This Row],[Quantity ]],"") -> 300 | F82: 46114 | G82: 🚚 Delivered | H82: ✅ Paid in Full | I82: Sarah | J82: UPI Sarah
A83: Crystal | B83: Rum Drop Medium | C83: 2 | D83: =IFERROR(VLOOKUP(Easter[[#This Row],[Product Name]],'Lookup sheet'!$A$1:$D$31,4,FALSE),"") -> 55 | E83: =IFERROR(Easter[[#This Row],[Price (Per Unit ₹)]]*Easter[[#This Row],[Quantity ]],"") -> 110 | F83: 46114 | G83: 🚚 Delivered | H83: ✅ Paid in Full | I83: Sarah | J83: UPI Sarah
A84: Debby | B84: Almond Crunch Dark Mini | C84: 35 | D84: =IFERROR(VLOOKUP(Easter[[#This Row],[Product Name]],'Lookup sheet'!$A$1:$D$31,4,FALSE),"") -> 25 | E84: =IFERROR(Easter[[#This Row],[Price (Per Unit ₹)]]*Easter[[#This Row],[Quantity ]],"") -> 875 | F84: 46117 | G84: 🚚 Delivered | H84: ✅ Paid in Full | I84: Sarah | J84: UPI Sarah
A85: Debby | B85: Almond Crunch Milk Mini | C85: 10 | D85: =IFERROR(VLOOKUP(Easter[[#This Row],[Product Name]],'Lookup sheet'!$A$1:$D$31,4,FALSE),"") -> 25 | E85: =IFERROR(Easter[[#This Row],[Price (Per Unit ₹)]]*Easter[[#This Row],[Quantity ]],"") -> 250 | F85: 46117 | G85: 🚚 Delivered | H85: ✅ Paid in Full | I85: Sarah | J85: UPI Sarah
... A89: Desi | B89: Almond Crunch Milk Mini | C89: 1 | D89: =IFERROR(VLOOKUP(Easter[[#This Row],[Product Name]],'Lookup sheet'!$A$1:$D$31,4,FALSE),"") -> 25 | E89: =IFERROR(Easter[[#This Row],[Price (Per Unit ₹)]]*Easter[[#This Row],[Quantity ]],"") -> 25 | F89: 46112 | G89: 🚚 Delivered | H89: ✅ Paid in Full | I89: Anna | J89: Cash
A90: Desi | B90: Blueberry Bliss Mini | C90: 1 | D90: =IFERROR(VLOOKUP(Easter[[#This Row],[Product Name]],'Lookup sheet'!$A$1:$D$31,4,FALSE),"") -> 30 | E90: =IFERROR(Easter[[#This Row],[Price (Per Unit ₹)]]*Easter[[#This Row],[Quantity ]],"") -> 30 | F90: 46112 | G90: 🚚 Delivered | H90: ✅ Paid in Full | I90: Anna | J90: Cash | K90: 30
A91: Desi | B91: Cookie and Dreams Mini | C91: 1 | D91: =IFERROR(VLOOKUP(Easter[[#This Row],[Product Name]],'Lookup sheet'!$A$1:$D$31,4,FALSE),"") -> 25 | E91: =IFERROR(Easter[[#This Row],[Price (Per Unit ₹)]]*Easter[[#This Row],[Quantity ]],"") -> 25 | F91: 46112 | G91: 🚚 Delivered | H91: ✅ Paid in Full | I91: Anna | J91: Cash
A92: Desi | B92: Mocha Pop mini | C92: 1 | D92: =IFERROR(VLOOKUP(Easter[[#This Row],[Product Name]],'Lookup sheet'!$A$1:$D$31,4,FALSE),"") -> 25 | E92: =IFERROR(Easter[[#This Row],[Price (Per Unit ₹)]]*Easter[[#This Row],[Quantity ]],"") -> 25 | F92: 46112 | G92: 🚚 Delivered | H92: ✅ Paid in Full | I92: Anna | J92: Cash
A93: Desi | B93: Plain Milk Mini | C93: 1 | D93: =IFERROR(VLOOKUP(Easter[[#This Row],[Product Name]],'Lookup sheet'!$A$1:$D$31,4,FALSE),"") -> 20 | E93: =IFERROR(Easter[[#This Row],[Price (Per Unit ₹)]]*Easter[[#This Row],[Quantity ]],"") -> 20 | F93: 46112 | G93: 🚚 Delivered | H93: ✅ Paid in Full | I93: Anna | J93: Cash
...

Sheet Order making
A3: ORDERS PER ITEM - Calculates automatically
A5: Total Quantity | B5: Order status
A6: Product Name | B6: ⏳ Pending | C6: 🚚 Delivered | E6: In Stock | F6: Order to make
A7: Almond Crunch Dark Large | B7: 0 | C7: 3 | E7: 1 | F7: =B7-E7 -> -1
A8: Almond Crunch Dark Medium | B8: 15 | C8: 68 | E8: 5 | F8: =B8-E8 -> 10
A9: Almond Crunch Dark Mini | B9: 0 | C9: 140 | E9: 0 | F9: =B9-E9 -> 0
A10: Almond Crunch Milk Large | B10: 0 | C10: 20 | E10: 3 | F10: =B10-E10 -> -3
A11: Almond Crunch Milk Medium | B11: 0 | C11: 42 | E11: 0 | F11: =B11-E11 -> 0
A12: Almond Crunch Milk Mini | B12: 2 | C12: 29 | E12: 0 | F12: =B12-E12 -> 2
A13: Blueberry Bliss Medium | B13: 0 | C13: 62 | E13: 0 | F13: =B13-E13 -> 0
A14: Blueberry Bliss Mini | B14: 1 | C14: 31 | E14: 7 | F14: =B14-E14 -> -6
A15: Bold & Plain Dark Large | B15: 0 | C15: 3 | E15: 0 | F15: =B15-E15 -> 0
A16: Bold & Plain Milk Large | B16: 0 | C16: 107 | E16: 0 | F16: =B16-E16 -> 0
A17: Bold & Plain White Large | B17: 0 | C17: 2 | E17: 0 | F17: =B17-E17 -> 0
A18: Bunny Pop Dark | B18: 0 | C18: 21 | E18: 0 | F18: =B18-E18 -> 0
... A36: Rum Drop Mini | B36: 2 | C36: 89 | E36: 0 | F36: =B36-E36 -> 2
A37: Grand Total | B37: 23 | C37: 1464 | E37: =SUM(E7:E36) -> 23 | F37: =SUM(F7:F36) -> 0

Sheet Production Sheet
A1: 🏭 PRODUCTION PLANNER | Mar 15 – Apr 5, 2026 (3 Weeks)
A2: 📅 WEEK-BY-WEEK PLAN
A3: Week 1 Mar 15–21 | B3: Take orders · Buy stock · Test blueberry recipe · Confirm all flavours
A4: Week 2 Mar 22–28 | B4: Bulk produce Mini & Medium · Confirm all orders · Start packaging
A5: Week 3 Mar 29–Apr 5 | B5: Produce Large eggs · Bunny Pops · Baskets · Final pack & deliver by Apr 4
A7: 📊 PLANNED QUANTITIES —calculates automatically | G7: Making cost Per Egg | J7: Chocolate slabs Bought
A8: Product | B8: Planned Qty ( DO NOT EDIT ! ) | C8: Making Cost (₹) | D8: Overhead 12% (₹) | E8: Total Cost (₹) | G8: Product | H8: Making Cost Per egg | J8: Type | K8: Per Slab (₹) | L8: Quantity bought | M8: Total
A9: Almond Crunch Dark Large | B9: =SUMIF(Easter[Product Name],'Production Sheet'!A9,Easter[[Quantity ]]) -> 3 | C9: =H9*B9 -> 168.9375 | D9: =(C9)*0.12 -> 20.2725 | E9: =C9+D9 -> 189.21 | G9: Almond Crunch Dark Large | H9: =VLOOKUP(Table2[[#This Row],[Product]],'Making cost '!$D$2:$O$31,12,FALSE) -> 56.3125 | J9: Dark | K9: 150 | L9: 13 | M9: =K9*L9 -> 1950
A10: Almond Crunch Dark Medium | B10: =SUMIF(Easter[Product Name],'Production Sheet'!A10,Easter[[Quantity ]]) -> 83 | C10: =H10*B10 -> 1768.9375 | D10: =(C10)*0.12 -> 212.2725 | E10: =C10+D10 -> 1981.21 | G10: Almond Crunch Dark Medium | H10: =VLOOKUP(Table2[[#This Row],[Product]],'Making cost '!$D$2:$O$31,12,FALSE) -> 21.3125 | J10: Milk | K10: 160 | L10: 13 | M10: =K10*L10 -> 2080
A11: Almond Crunch Dark Mini | B11: =SUMIF(Easter[Product Name],'Production Sheet'!A11,Easter[[Quantity ]]) -> 140 | C11: =H11*B11 -> 1570.5278 | D11: =(C11)*0.12 -> 188.46333 | E11: =C11+D11 -> 1758.9911 | G11: Almond Crunch Dark Mini | H11: =VLOOKUP(Table2[[#This Row],[Product]],'Making cost '!$D$2:$O$31,12,FALSE) -> 11.218056 | J11: White | K11: 170 | L11: 3 | M11: =K11*L11 -> 510
A12: Almond Crunch Milk Large | B12: =SUMIF(Easter[Product Name],'Production Sheet'!A12,Easter[[Quantity ]]) -> 20 | C12: =H12*B12 -> 1162.9167 | D12: =(C12)*0.12 -> 139.55 | E12: =C12+D12 -> 1302.4667 | G12: Almond Crunch Milk Large | H12: =VLOOKUP(Table2[[#This Row],[Product]],'Making cost '!$D$2:$O$31,12,FALSE) -> 58.145833 | J12: Total | L12: =SUM(L9:L11) -> 29 | M12: =SUM(M9:M11) -> 4540
A13: Almond Crunch Milk Medium | B13: =SUMIF(Easter[Product Name],'Production Sheet'!A13,Easter[[Quantity ]]) -> 42 | C13: =H13*B13 -> 930.125 | D13: =(C13)*0.12 -> 111.615 | E13: =C13+D13 -> 1041.74 | G13: Almond Crunch Milk Medium | H13: =VLOOKUP(Table2[[#This Row],[Product]],'Making cost '!$D$2:$O$31,12,FALSE) -> 22.145833
A14: Almond Crunch Milk Mini | B14: =SUMIF(Easter[Product Name],'Production Sheet'!A14,Easter[[Quantity ]]) -> 31 | C14: =H14*B14 -> 359.2412 | D14: =(C14)*0.12 -> 43.108944 | E14: =C14+D14 -> 402.35015 | G14: Almond Crunch Milk Mini | H14: =VLOOKUP(Table2[[#This Row],[Product]],'Making cost '!$D$2:$O$31,12,FALSE) -> 11.588426 | J14: Chocolate slabs needed
A15: Blueberry Bliss Medium | B15: =SUMIF(Easter[Product Name],'Production Sheet'!A15,Easter[[Quantity ]]) -> 62 | C15: =H15*B15 -> 1393.7083 | D15: =(C15)*0.12 -> 167.245 | E15: =C15+D15 -> 1560.9533 | G15: Blueberry Bliss Medium | H15: =VLOOKUP(Table2[[#This Row],[Product]],'Making cost '!$D$2:$O$31,12,FALSE) -> 22.479167 | J15: Type | K15: Size | L15: Output per slab | M15: Slabs needed | N15: Quantity eggs | O15: Total Cost for slabs
A16: Blueberry Bliss Mini | B16: =SUMIF(Easter[Product Name],'Production Sheet'!A16,Easter[[Quantity ]]) -> 32 | C16: =H16*B16 -> 366.68148 | D16: =(C16)*0.12 -> 44.001778 | E16: =C16+D16 -> 410.68326 | G16: Blueberry Bliss Mini | H16: =VLOOKUP(Table2[[#This Row],[Product]],'Making cost '!$D$2:$O$31,12,FALSE) -> 11.458796 | J16: Dark | K16: Mini | L16: 27 | M16: =N16/L16 -> 10.777778 | N16: =SUMIFS('Lookup sheet'!$E$2:$E$31,'Lookup sheet'!$B$2:$B$31,'Production Sheet'!K16,'Lookup sheet'!$C$2:$C$31,'Production Sheet'!J16) -> 291 | O16: =M16*$K$9 -> 1616.6667
A17: Bold & Plain Dark Large | B17: =SUMIF(Easter[Product Name],'Production Sheet'!A17,Easter[[Quantity ]]) -> 3 | C17: =H17*B17 -> 155.4375 | D17: =(C17)*0.12 -> 18.6525 | E17: =C17+D17 -> 174.09 | G17: Bold & Plain Dark Large | H17: =VLOOKUP(Table2[[#This Row],[Product]],'Making cost '!$D$2:$O$31,12,FALSE) -> 51.8125 | J17: Dark | K17: Medium | L17: 12 | M17: =N17/L17 -> 18.083333 | N17: =SUMIFS('Lookup sheet'!$E$2:$E$31,'Lookup sheet'!$B$2:$B$31,'Production Sheet'!K17,'Lookup sheet'!$C$2:$C$31,'Production Sheet'!J17) -> 217 | O17: =M17*$K$9 -> 2712.5
A18: Bold & Plain Milk Large | B18: =SUMIF(Easter[Product Name],'Production Sheet'!A18,Easter[[Quantity ]]) -> 107 | C18: =H18*B18 -> 5900.6042 | D18: =(C18)*0.12 -> 708.0725 | E18: =C18+D18 -> 6608.6767 | G18: Bold & Plain Milk Large | H18: =VLOOKUP(Table2[[#This Row],[Product]],'Making cost '!$D$2:$O$31,12,FALSE) -> 55.145833 | J18: Dark | K18: Large | L18: 3 | M18: =N18/L18 -> 12 | N18: =SUMIFS('Lookup sheet'!$E$2:$E$31,'Lookup sheet'!$B$2:$B$31,'Production Sheet'!K18,'Lookup sheet'!$C$2:$C$31,'Production Sheet'!J18) -> 36 | O18: =M18*$K$9 -> 1800
A19: Bold & Plain White Large | B19: =SUMIF(Easter[Product Name],'Production Sheet'!A19,Easter[[Quantity ]]) -> 2 | C19: =H19*B19 -> 116.95833 | D19: =(C19)*0.12 -> 14.035 | E19: =C19+D19 -> 130.99333 | G19: Bold & Plain White Large | H19: =VLOOKUP(Table2[[#This Row],[Product]],'Making cost '!$D$2:$O$31,12,FALSE) -> 58.479167 | J19: Milk | K19: Mini | L19: 27 | M19: =N19/L19 -> 5.8888889 | N19: =SUMIFS('Lookup sheet'!$E$2:$E$31,'Lookup sheet'!$B$2:$B$31,'Production Sheet'!K19,'Lookup sheet'!$C$2:$C$31,'Production Sheet'!J19) -> 159 | O19: =M19*$K$10 -> 942.22222
A20: Bunny Pop Dark | B20: =SUMIF(Easter[Product Name],'Production Sheet'!A20,Easter[[Quantity ]]) -> 21 | C20: =H20*B20 -> 104.1375 | D20: =(C20)*0.12 -> 12.4965 | E20: =C20+D20 -> 116.634 | G20: Bunny Pop Dark | H20: =VLOOKUP(Table2[[#This Row],[Product]],'Making cost '!$D$2:$O$31,12,FALSE) -> 4.9589286 | J20: Milk | K20: Medium | L20: 12 | M20: =N20/L20 -> 13.416667 | N20: =SUMIFS('Lookup sheet'!$E$2:$E$31,'Lookup sheet'!$B$2:$B$31,'Production Sheet'!K20,'Lookup sheet'!$C$2:$C$31,'Production Sheet'!J20) -> 161 | O20: =M20*$K$10 -> 2146.6667
A21: Bunny Pop Milk | B21: =SUMIF(Easter[Product Name],'Production Sheet'!A21,Easter[[Quantity ]]) -> 30 | C21: =H21*B21 -> 155.91071 | D21: =(C21)*0.12 -> 18.709286 | E21: =C21+D21 -> 174.62 | G21: Bunny Pop Milk | H21: =VLOOKUP(Table2[[#This Row],[Product]],'Making cost '!$D$2:$O$31,12,FALSE) -> 5.1970238 | J21: Milk | K21: Large | L21: 3 | M21: =N21/L21 -> 48.333333 | N21: =SUMIFS('Lookup sheet'!$E$2:$E$31,'Lookup sheet'!$B$2:$B$31,'Production Sheet'!K21,'Lookup sheet'!$C$2:$C$31,'Production Sheet'!J21) -> 145 | O21: =M21*$K$10 -> 7733.3333
A22: Cookie And Dreams Large | B22: =SUMIF(Easter[Product Name],'Production Sheet'!A22,Easter[[Quantity ]]) -> 12 | C22: =H22*B22 -> 716.15 | D22: =(C22)*0.12 -> 85.938 | E22: =C22+D22 -> 802.088 | G22: Cookie And Dreams Large | H22: =VLOOKUP(Table2[[#This Row],[Product]],'Making cost '!$D$2:$O$31,12,FALSE) -> 59.679167 | J22: White | K22: Mini | L22: 27 | M22: =N22/L22 -> 4.7037037 | N22: =SUMIFS('Lookup sheet'!$E$2:$E$31,'Lookup sheet'!$B$2:$B$31,'Production Sheet'!K22,'Lookup sheet'!$C$2:$C$31,'Production Sheet'!J22) -> 127 | O22: =M22*$K$11 -> 799.62963
A23: Cookie and Dreams Medium | B23: =SUMIF(Easter[Product Name],'Production Sheet'!A23,Easter[[Quantity ]]) -> 83 | C23: =H23*B23 -> 1757.8708 | D23: =(C23)*0.12 -> 210.9445 | E23: =C23+D23 -> 1968.8153 | G23: Cookie and Dreams Medium | H23: =VLOOKUP(Table2[[#This Row],[Product]],'Making cost '!$D$2:$O$31,12,FALSE) -> 21.179167 | J23: White | K23: Medium | L23: 12 | M23: =N23/L23 -> 12.916667 | N23: =SUMIFS('Lookup sheet'!$E$2:$E$31,'Lookup sheet'!$B$2:$B$31,'Production Sheet'!K23,'Lookup sheet'!$C$2:$C$31,'Production Sheet'!J23) -> 155 | O23: =M23*$K$11 -> 2195.8333
A24: Cookie and Dreams Mini | B24: =SUMIF(Easter[Product Name],'Production Sheet'!A24,Easter[[Quantity ]]) -> 89 | C24: =H24*B24 -> 904.13287 | D24: =(C24)*0.12 -> 108.49594 | E24: =C24+D24 -> 1012.6288 | G24: Cookie and Dreams Mini | H24: =VLOOKUP(Table2[[#This Row],[Product]],'Making cost '!$D$2:$O$31,12,FALSE) -> 10.158796 | J24: White | K24: Large | L24: 3 | M24: =N24/L24 -> 4.6666667 | N24: =SUMIFS('Lookup sheet'!$E$2:$E$31,'Lookup sheet'!$B$2:$B$31,'Production Sheet'!K24,'Lookup sheet'!$C$2:$C$31,'Production Sheet'!J24) -> 14 | O24: =M24*$K$11 -> 793.33333
A25: Mini Egglet Basket | B25: =SUMIF(Easter[Product Name],'Production Sheet'!A25,Easter[[Quantity ]]) -> 79 | C25: =H25*B25 -> 3931.2375 | D25: =(C25)*0.12 -> 471.7485 | E25: =C25+D25 -> 4402.986 | G25: Mini Egglet Basket | H25: =VLOOKUP(Table2[[#This Row],[Product]],'Making cost '!$D$2:$O$31,12,FALSE) -> 49.7625 | J25: Milk | K25: Party Popper | L25: 6 | M25: =N25/L25 -> 8.6666667 | N25: =SUMIF(Easter[Product Name],'Production Sheet'!K25,Easter[[Quantity ]]) -> 52 | O25: =M25*$K$10 -> 1386.6667
A26: Mocha Pop Large | B26: =SUMIF(Easter[Product Name],'Production Sheet'!A26,Easter[[Quantity ]]) -> 18 | C26: =H26*B26 -> 1019.625 | D26: =(C26)*0.12 -> 122.355 | E26: =C26+D26 -> 1141.98 | G26: Mocha Pop Large | H26: =VLOOKUP(Table2[[#This Row],[Product]],'Making cost '!$D$2:$O$31,12,FALSE) -> 56.645833 | J26: Milk | K26: Bunny Pop Milk | L26: 42 | M26: =N26/L26 -> 0.71428571 | N26: =SUMIF(Easter[Product Name],'Production Sheet'!K26,Easter[[Quantity ]]) -> 30 | O26: =M26*$K$10 -> 114.28571
A27: Mocha Pop Medium | B27: =SUMIF(Easter[Product Name],'Production Sheet'!A27,Easter[[Quantity ]]) -> 81 | C27: =H27*B27 -> 1672.3125 | D27: =(C27)*0.12 -> 200.6775 | E27: =C27+D27 -> 1872.99 | G27: Mocha Pop Medium | H27: =VLOOKUP(Table2[[#This Row],[Product]],'Making cost '!$D$2:$O$31,12,FALSE) -> 20.645833 | J27: Dark | K27: Bunny Pop Dark | L27: 42 | M27: =N27/L27 -> 0.5 | N27: =SUMIF(Easter[Product Name],'Production Sheet'!K27,Easter[[Quantity ]]) -> 21 | O27: =M27*$K$9 -> 75
A28: Mocha Pop mini | B28: =SUMIF(Easter[Product Name],'Production Sheet'!A28,Easter[[Quantity ]]) -> 101 | C28: =H28*B28 -> 1018.931 | D28: =(C28)*0.12 -> 122.27172 | E28: =C28+D28 -> 1141.2027 | G28: Mocha Pop mini | H28: =VLOOKUP(Table2[[#This Row],[Product]],'Making cost '!$D$2:$O$31,12,FALSE) -> 10.088426 | J28: Milk | K28: Mini Egglet Basket | L28: 5 | M28: =N28/L28 -> 15.8 | N28: =SUMIF(Easter[Product Name],'Production Sheet'!K28,Easter[[Quantity ]]) -> 79 | O28: =M28*$K$10 -> 2528
A29: Party Popper | B29: =SUMIF(Easter[Product Name],'Production Sheet'!A29,Easter[[Quantity ]]) -> 52 | C29: =H29*B29 -> 1558.9167 | D29: =(C29)*0.12 -> 187.07 | E29: =C29+D29 -> 1745.9867 | G29: Party Popper | H29: =VLOOKUP(Table2[[#This Row],[Product]],'Making cost '!$D$2:$O$31,12,FALSE) -> 29.979167 | J29: Total | M29: =SUM(M16:M27) -> 140.66799 | N29: =SUM(N16:N28) -> 1487 | O29: =SUM(O16:O27) -> 22316.138
A30: Plain Dark Medium | B30: =SUMIF(Easter[Product Name],'Production Sheet'!A30,Easter[[Quantity ]]) -> 44 | C30: =H30*B30 -> 805.75 | D30: =(C30)*0.12 -> 96.69 | E30: =C30+D30 -> 902.44 | G30: Plain Dark Medium | H30: =VLOOKUP(Table2[[#This Row],[Product]],'Making cost '!$D$2:$O$31,12,FALSE) -> 18.3125 | N30: Discounted Price
A31: Plain Dark Mini | B31: =SUMIF(Easter[Product Name],'Production Sheet'!A31,Easter[[Quantity ]]) -> 60 | C31: =H31*B31 -> 493.08333 | D31: =(C31)*0.12 -> 59.17 | E31: =C31+D31 -> 552.25333 | G31: Plain Dark Mini | H31: =VLOOKUP(Table2[[#This Row],[Product]],'Making cost '!$D$2:$O$31,12,FALSE) -> 8.2180556
A32: Plain Milk Medium | B32: =SUMIF(Easter[Product Name],'Production Sheet'!A32,Easter[[Quantity ]]) -> 38 | C32: =H32*B32 -> 727.54167 | D32: =(C32)*0.12 -> 87.305 | E32: =C32+D32 -> 814.84667 | G32: Plain Milk Medium | H32: =VLOOKUP(Table2[[#This Row],[Product]],'Making cost '!$D$2:$O$31,12,FALSE) -> 19.145833
A33: Plain Milk Mini | B33: =SUMIF(Easter[Product Name],'Production Sheet'!A33,Easter[[Quantity ]]) -> 27 | C33: =H33*B33 -> 231.8875 | D33: =(C33)*0.12 -> 27.8265 | E33: =C33+D33 -> 259.714 | G33: Plain Milk Mini | H33: =VLOOKUP(Table2[[#This Row],[Product]],'Making cost '!$D$2:$O$31,12,FALSE) -> 8.5884259
A34: Plain White Mini | B34: =SUMIF(Easter[Product Name],'Production Sheet'!A34,Easter[[Quantity ]]) -> 6 | C34: =H34*B34 -> 53.752778 | D34: =(C34)*0.12 -> 6.4503333 | E34: =C34+D34 -> 60.203111 | G34: Plain White Mini | H34: =VLOOKUP(Table2[[#This Row],[Product]],'Making cost '!$D$2:$O$31,12,FALSE) -> 8.9587963
A35: Rum Drop Large | B35: =SUMIF(Easter[Product Name],'Production Sheet'!A35,Easter[[Quantity ]]) -> 30 | C35: =H35*B35 -> 1644.375 | D35: =(C35)*0.12 -> 197.325 | E35: =C35+D35 -> 1841.7 | G35: Rum Drop Large | H35: =VLOOKUP(Table2[[#This Row],[Product]],'Making cost '!$D$2:$O$31,12,FALSE) -> 54.8125
A36: Rum Drop Medium | B36: =SUMIF(Easter[Product Name],'Production Sheet'!A36,Easter[[Quantity ]]) -> 90 | C36: =H36*B36 -> 1783.125 | D36: =(C36)*0.12 -> 213.975 | E36: =C36+D36 -> 1997.1 | G36: Rum Drop Medium | H36: =VLOOKUP(Table2[[#This Row],[Product]],'Making cost '!$D$2:$O$31,12,FALSE) -> 19.8125
A37: Rum Drop Mini | B37: =SUMIF(Easter[Product Name],'Production Sheet'!A37,Easter[[Quantity ]]) -> 91 | C37: =H37*B37 -> 884.34306 | D37: =(C37)*0.12 -> 106.12117 | E37: =C37+D37 -> 990.46422 | G37: Rum Drop Mini | H37: =VLOOKUP(Table2[[#This Row],[Product]],'Making cost '!$D$2:$O$31,12,FALSE) -> 9.7180556
A38: Total | B38: =SUM(B9:B37) -> 1477 | C38: =SUM(C9:C37) -> 33357.158 | D38: =SUM(D9:D37) -> 4002.859 | E38: =SUM(E9:E37) -> 37360.017

Sheet Making cost 
A1: Material Cost ( Can Edit) | D1: Product Name | E1: Chocolate cost | F1: Box Cost | G1: Plastic Cost | H1: Ribbon Cost | I1: Almond Cost | J1: Blueberry cost | K1: Coffee cost | L1: Rum cost | M1: C&D cost | N1: Stick Cost | O1: Making Cost | P1: Margin
A2: Item | B2: Value | D2: Almond Crunch Dark Large | E2: =$B$4/$B$8 -> 50 | F2: =$B$25/$B$24 -> 3 | G2: 0 | H2: =IFERROR($B$15/$B$17,"0") -> 0.3125 | I2: =$B$18 -> 3 | J2: 0 | K2: 0 | L2: 0 | M2: 0 | N2: 0 | O2: =SUM(E2:N2) -> 56.3125 | P2: =O2/'Lookup sheet'!D2 -> 0.43317308
A3: Milk Slab Price | B3: 160 | D3: Almond Crunch Dark Medium | E3: =$B$4/$B$7 -> 12.5 | F3: =$B$10/$B$12 -> 2 | G3: =$B$13/$B$28 -> 3.5 | H3: =IFERROR($B$15/$B$17,"0") -> 0.3125 | I3: =$B$18 -> 3 | J3: 0 | K3: 0 | L3: 0 | M3: 0 | N3: 0 | O3: =SUM(E3:N3) -> 21.3125 | P3: =O3/'Lookup sheet'!D3 -> 0.35520833
A4: Dark Slab Price | B4: 150 | D4: Almond Crunch Dark Mini | E4: =$B$4/$B$6 -> 5.5555556 | F4: =$B$10/$B$11 -> 0.6 | G4: =$B$13/$B$27 -> 1.75 | H4: =IFERROR($B$15/$B$17,"0") -> 0.3125 | I4: =$B$18 -> 3 | J4: 0 | K4: 0 | L4: 0 | M4: 0 | N4: 0 | O4: =SUM(E4:N4) -> 11.218056 | P4: =O4/'Lookup sheet'!D4 -> 0.44872222
A5: White Slab Price | B5: 170 | D5: Almond Crunch Milk Large | E5: =$B$3/$B$8 -> 53.333333 | F5: =$B$10/$B$26 -> 1.5 | G5: 0 | H5: =IFERROR($B$15/$B$17,"0") -> 0.3125 | I5: =$B$18 -> 3 | J5: 0 | K5: 0 | L5: 0 | M5: 0 | N5: 0 | O5: =SUM(E5:N5) -> 58.145833 | P5: =O5/'Lookup sheet'!D5 -> 0.44727564
A6: Mini Eggs per Slab | B6: 27 | D6: Almond Crunch Milk Medium | E6: =$B$3/$B$7 -> 13.333333 | F6: =$B$10/$B$12 -> 2 | G6: =$B$13/$B$28 -> 3.5 | H6: =IFERROR($B$15/$B$17,"0") -> 0.3125 | I6: =$B$18 -> 3 | J6: 0 | K6: 0 | L6: 0 | M6: 0 | N6: 0 | O6: =SUM(E6:N6) -> 22.145833 | P6: =O6/'Lookup sheet'!D6 -> 0.36909722
A7: Medium Eggs per Slab | B7: 12 | D7: Almond Crunch Milk Mini | E7: =$B$3/$B$6 -> 5.9259259 | F7: =$B$10/$B$11 -> 0.6 | G7: =$B$13/$B$27 -> 1.75 | H7: =IFERROR($B$15/$B$17,"0") -> 0.3125 | I7: =$B$18 -> 3 | J7: 0 | K7: 0 | L7: 0 | M7: 0 | N7: 0 | O7: =SUM(E7:N7) -> 11.588426 | P7: =O7/'Lookup sheet'!D7 -> 0.46353704
A8: Large Eggs per Slab | B8: 3 | D8: Blueberry Bliss Medium | E8: =$B$5/$B$7 -> 14.166667 | F8: =$B$10/$B$12 -> 2 | G8: =$B$13/$B$28 -> 3.5 | H8: =IFERROR($B$15/$B$17,"0") -> 0.3125 | I8: 0 | J8: =$B$19 -> 2.5 | K8: 0 | L8: 0 | M8: 0 | N8: 0 | O8: =SUM(E8:N8) -> 22.479167 | P8: =O8/'Lookup sheet'!D8 -> 0.34583333
A9: Bunny Pops per Slab | B9: 42 | D9: Blueberry Bliss Mini | E9: =$B$5/$B$6 -> 6.2962963 | F9: =$B$10/$B$11 -> 0.6 | G9: =$B$13/$B$27 -> 1.75 | H9: =IFERROR($B$15/$B$17,"0") -> 0.3125 | I9: 0 | J9: =$B$19 -> 2.5 | K9: 0 | L9: 0 | M9: 0 | N9: 0 | O9: =SUM(E9:N9) -> 11.458796 | P9: =O9/'Lookup sheet'!D9 -> 0.38195988
A10: Box Cost | B10: 6 | D10: Bold & Plain Dark Large | E10: =$B$4/$B$8 -> 50 | F10: =$B$10/$B$26 -> 1.5 | G10: 0 | H10: =IFERROR($B$15/$B$17,"0") -> 0.3125 | I10: 0 | J10: 0 | K10: 0 | L10: 0 | M10: 0 | N10: 0 | O10: =SUM(E10:N10) -> 51.8125 | P10: =O10/'Lookup sheet'!D10 -> 0.47102273
A11: Mini Eggs per Box | B11: 10 | D11: Bold & Plain Milk Large | E11: =$B$3/$B$8 -> 53.333333 | F11: =$B$10/$B$26 -> 1.5 | G11: 0 | H11: =IFERROR($B$15/$B$17,"0") -> 0.3125 | I11: 0 | J11: 0 | K11: 0 | L11: 0 | M11: 0 | N11: 0 | O11: =SUM(E11:N11) -> 55.145833 | P11: =O11/'Lookup sheet'!D11 -> 0.50132576
A12: Medium Eggs per Box | B12: 3 | D12: Bold & Plain White Large | E12: =$B$5/$B$8 -> 56.666667 | F12: =$B$10/$B$26 -> 1.5 | G12: 0 | H12: =IFERROR($B$15/$B$17,"0") -> 0.3125 | I12: 0 | J12: 0 | K12: 0 | L12: 0 | M12: 0 | N12: 0 | O12: =SUM(E12:N12) -> 58.479167 | P12: =O12/'Lookup sheet'!D12 -> 0.53162879
A13: Plastic Sheet Cost | B13: 7 | D13: Bunny Pop Dark | E13: =$B$4/$B$9 -> 3.5714286 | F13: 0 | G13: =$B$13/$B$14 -> 0.875 | H13: =IFERROR($B$15/$B$17,"0") -> 0.3125 | I13: 0 | J13: 0 | K13: 0 | L13: 0 | M13: 0 | N13: =$B$31/$B$32 -> 0.2 | O13: =SUM(E13:N13) -> 4.9589286 | P13: =O13/'Lookup sheet'!D13 -> 0.12397321
A14: Bunny Pops per Sheet | B14: 8 | D14: Bunny Pop Milk | E14: =$B$3/$B$9 -> 3.8095238 | F14: 0 | G14: =$B$13/$B$14 -> 0.875 | H14: =IFERROR($B$15/$B$17,"0") -> 0.3125 | I14: 0 | J14: 0 | K14: 0 | L14: 0 | M14: 0 | N14: =$B$31/$B$32 -> 0.2 | O14: =SUM(E14:N14) -> 5.1970238 | P14: =O14/'Lookup sheet'!D14 -> 0.1299256
A15: Ribbon Cost | B15: 25 | D15: Cookie And Dreams Large | E15: =$B$5/$B$8 -> 56.666667 | F15: =$B$10/$B$26 -> 1.5 | G15: 0 | H15: =IFERROR($B$15/$B$17,"0") -> 0.3125 | I15: 0 | J15: 0 | K15: 0 | L15: 0 | M15: =$B$22 -> 1.2 | N15: 0 | O15: =SUM(E15:N15) -> 59.679167 | P15: =O15/'Lookup sheet'!D15 -> 0.45907051
A16: Party Popper Per Slab | B16: 6 | D16: Cookie and Dreams Medium | E16: =$B$5/$B$7 -> 14.166667 | F16: =$B$10/$B$12 -> 2 | G16: =$B$13/$B$28 -> 3.5 | H16: =IFERROR($B$15/$B$17,"0") -> 0.3125 | I16: 0 | J16: 0 | K16: 0 | L16: 0 | M16: =$B$22 -> 1.2 | N16: 0 | O16: =SUM(E16:N16) -> 21.179167 | P16: =O16/'Lookup sheet'!D16 -> 0.35298611
A17: Orders Per Ribbon | B17: 80 | D17: Cookie and Dreams Mini | E17: =$B$5/$B$6 -> 6.2962963 | F17: =$B$10/$B$11 -> 0.6 | G17: =$B$13/$B$27 -> 1.75 | H17: =IFERROR($B$15/$B$17,"0") -> 0.3125 | I17: 0 | J17: 0 | K17: 0 | L17: 0 | M17: =$B$22 -> 1.2 | N17: 0 | O17: =SUM(E17:N17) -> 10.158796 | P17: =O17/'Lookup sheet'!D17 -> 0.40635185
A18: Almonds Cost per Egg | B18: 3 | D18: Mini Egglet Basket | E18: =$B$3/$B$33 -> 32 | F18: =B10 -> 6 | G18: =$B$13/$B$27 -> 1.75 | H18: =IFERROR($B$15/$B$17,"0") -> 0.3125 | I18: =$B$18 -> 3 | J18: =$B$19 -> 2.5 | K18: =$B$20 -> 1.5 | L18: =$B$21 -> 1.5 | M18: =$B$22 -> 1.2 | N18: 0 | O18: =SUM(E18:N18) -> 49.7625 | P18: =O18/'Lookup sheet'!D18 -> 0.33175
A19: Blueberry Cost per Egg | B19: 2.5 | D19: Mocha Pop Large | E19: =$B$3/$B$8 -> 53.333333 | F19: =$B$10/$B$26 -> 1.5 | G19: 0 | H19: =IFERROR($B$15/$B$17,"0") -> 0.3125 | I19: 0 | J19: 0 | K19: =$B$20 -> 1.5 | L19: 0 | M19: 0 | N19: 0 | O19: =SUM(E19:N19) -> 56.645833 | P19: =O19/'Lookup sheet'!D19 -> 0.43573718
A20: Coffee Cost per Egg | B20: 1.5 | D20: Mocha Pop Medium | E20: =$B$3/$B$7 -> 13.333333 | F20: =$B$10/$B$12 -> 2 | G20: =$B$13/$B$28 -> 3.5 | H20: =IFERROR($B$15/$B$17,"0") -> 0.3125 | I20: 0 | J20: 0 | K20: =$B$20 -> 1.5 | L20: 0 | M20: 0 | N20: 0 | O20: =SUM(E20:N20) -> 20.645833 | P20: =O20/'Lookup sheet'!D20 -> 0.37537879
A21: Rum Cost per Egg | B21: 1.5 | D21: Mocha Pop mini | E21: =$B$3/$B$6 -> 5.9259259 | F21: =$B$10/$B$11 -> 0.6 | G21: =$B$13/$B$27 -> 1.75 | H21: =IFERROR($B$15/$B$17,"0") -> 0.3125 | I21: 0 | J21: 0 | K21: =$B$20 -> 1.5 | L21: 0 | M21: 0 | N21: 0 | O21: =SUM(E21:N21) -> 10.088426 | P21: =O21/'Lookup sheet'!D21 -> 0.40353704
A22: Cookie & Dreams per Egg | B22: 1.2 | D22: Party Popper | E22: =$B$3/$B$16 -> 26.666667 | F22: =$B$25/$B$24 -> 3 | G22: 0 | H22: =IFERROR($B$15/$B$17,"0") -> 0.3125 | I22: 0 | J22: 0 | K22: 0 | L22: 0 | M22: 0 | N22: 0 | O22: =SUM(E22:N22) -> 29.979167 | P22: =O22/'Lookup sheet'!D22 -> 0.29979167
A23: Plastic Glass | B23: 5 | D23: Plain Dark Medium | E23: =$B$4/$B$7 -> 12.5 | F23: =$B$10/$B$12 -> 2 | G23: =$B$13/$B$28 -> 3.5 | H23: =IFERROR($B$15/$B$17,"0") -> 0.3125 | I23: 0 | J23: 0 | K23: 0 | L23: 0 | M23: 0 | N23: 0 | O23: =SUM(E23:N23) -> 18.3125 | P23: =O23/'Lookup sheet'!D23 -> 0.36625
A24: party pooper per box | B24: 4 | D24: Plain Dark Mini | E24: =$B$4/$B$6 -> 5.5555556 | F24: =$B$10/$B$11 -> 0.6 | G24: =$B$13/$B$27 -> 1.75 | H24: =IFERROR($B$15/$B$17,"0") -> 0.3125 | I24: 0 | J24: 0 | K24: 0 | L24: 0 | M24: 0 | N24: 0 | O24: =SUM(E24:N24) -> 8.2180556 | P24: =O24/'Lookup sheet'!D24 -> 0.41090278
A25: Big box | B25: 12 | D25: Plain Milk Medium | E25: =$B$3/$B$7 -> 13.333333 | F25: =$B$10/$B$12 -> 2 | G25: =$B$13/$B$28 -> 3.5 | H25: =IFERROR($B$15/$B$17,"0") -> 0.3125 | I25: 0 | J25: 0 | K25: 0 | L25: 0 | M25: 0 | N25: 0 | O25: =SUM(E25:N25) -> 19.145833 | P25: =O25/'Lookup sheet'!D25 -> 0.38291667
A26: Large Egg per box (Big Box | B26: 4 | D26: Plain Milk Mini | E26: =$B$3/$B$6 -> 5.9259259 | F26: =$B$10/$B$11 -> 0.6 | G26: =$B$13/$B$27 -> 1.75 | H26: =IFERROR($B$15/$B$17,"0") -> 0.3125 | I26: 0 | J26: 0 | K26: 0 | L26: 0 | M26: 0 | N26: 0 | O26: =SUM(E26:N26) -> 8.5884259 | P26: =O26/'Lookup sheet'!D26 -> 0.4294213
A27: Mini Eggs per plastic | B27: 4 | D27: Plain White Medium | E27: =$B$5/$B$7 -> 14.166667 | F27: =$B$10/$B$12 -> 2 | G27: =$B$13/$B$28 -> 3.5 | H27: =IFERROR($B$15/$B$17,"0") -> 0.3125 | I27: 0 | J27: 0 | K27: 0 | L27: 0 | M27: 0 | N27: 0 | O27: =SUM(E27:N27) -> 19.979167 | P27: =O27/'Lookup sheet'!D27 -> 0.39958333
A28: Medium Eggs per plastic | B28: 2 | D28: Plain White Mini | E28: =$B$5/$B$6 -> 6.2962963 | F28: =$B$10/$B$11 -> 0.6 | G28: =$B$13/$B$27 -> 1.75 | H28: =IFERROR($B$15/$B$17,"0") -> 0.3125 | I28: 0 | J28: 0 | K28: 0 | L28: 0 | M28: 0 | N28: 0 | O28: =SUM(E28:N28) -> 8.9587963 | P28: =O28/'Lookup sheet'!D28 -> 0.44793981
A29: Bunny Pop Milk per box | B29: 20 | D29: Rum Drop Large | E29: =$B$4/$B$8 -> 50 | F29: =$B$25/$B$24 -> 3 | G29: 0 | H29: =IFERROR($B$15/$B$17,"0") -> 0.3125 | I29: 0 | J29: 0 | K29: 0 | L29: =$B$21 -> 1.5 | M29: 0 | N29: 0 | O29: =SUM(E29:N29) -> 54.8125 | P29: =O29/'Lookup sheet'!D29 -> 0.42163462
A30: Labels | B30: 30 | D30: Rum Drop Medium | E30: =$B$4/$B$7 -> 12.5 | F30: =$B$10/$B$12 -> 2 | G30: =$B$13/$B$28 -> 3.5 | H30: =IFERROR($B$15/$B$17,"0") -> 0.3125 | I30: 0 | J30: 0 | K30: 0 | L30: =$B$21 -> 1.5 | M30: 0 | N30: 0 | O30: =SUM(E30:N30) -> 19.8125 | P30: =O30/'Lookup sheet'!D30 -> 0.36022727
A31: Stick box | B31: 20 | D31: Rum Drop Mini | E31: =$B$4/$B$6 -> 5.5555556 | F31: =$B$10/$B$11 -> 0.6 | G31: =$B$13/$B$27 -> 1.75 | H31: =IFERROR($B$15/$B$17,"0") -> 0.3125 | I31: 0 | J31: 0 | K31: 0 | L31: =$B$21 -> 1.5 | M31: 0 | N31: 0 | O31: =SUM(E31:N31) -> 9.7180556 | P31: =O31/'Lookup sheet'!D31 -> 0.38872222
A32: Number of stick per box | B32: 100
A33: Mini egglet per slab | B33: 5

Sheet Lookup sheet
A1: Product name | B1: Size | C1: Chocolate type | D1: Cost | E1: Quantity | G1: ⏳ Pending | I1: 💰Advance Paid
A2: Almond Crunch Dark Large | B2: Large | C2: Dark | D2: 130 | E2: =SUMIF(Easter[Product Name],'Lookup sheet'!A2,Easter[[Quantity ]]) -> 3 | G2: 🔄 In Progress | I2: ❌ No payment Made
A3: Almond Crunch Dark Medium | B3: Medium | C3: Dark | D3: 60 | E3: =SUMIF(Easter[Product Name],'Lookup sheet'!A3,Easter[[Quantity ]]) -> 83 | G3: ✅ Ready | I3: ✅ Paid in Full
A4: Almond Crunch Dark Mini | B4: Mini | C4: Dark | D4: 25 | E4: =SUMIF(Easter[Product Name],'Lookup sheet'!A4,Easter[[Quantity ]]) -> 140 | G4: 🚚 Delivered
A5: Almond Crunch Milk Large | B5: Large | C5: Milk | D5: 130 | E5: =SUMIF(Easter[Product Name],'Lookup sheet'!A5,Easter[[Quantity ]]) -> 20 | G5: ❌ Cancelled
A6: Almond Crunch Milk Medium | B6: Medium | C6: Milk | D6: 60 | E6: =SUMIF(Easter[Product Name],'Lookup sheet'!A6,Easter[[Quantity ]]) -> 42
A7: Almond Crunch Milk Mini | B7: Mini | C7: Milk | D7: 25 | E7: =SUMIF(Easter[Product Name],'Lookup sheet'!A7,Easter[[Quantity ]]) -> 31 | G7: Sarah
A8: Blueberry Bliss Medium | B8: Medium | C8: White | D8: 65 | E8: =SUMIF(Easter[Product Name],'Lookup sheet'!A8,Easter[[Quantity ]]) -> 62 | G8: Anna
A9: Blueberry Bliss Mini | B9: Mini | C9: White | D9: 30 | E9: =SUMIF(Easter[Product Name],'Lookup sheet'!A9,Easter[[Quantity ]]) -> 32
A10: Bold & Plain Dark Large | B10: Large | C10: Dark | D10: 110 | E10: =SUMIF(Easter[Product Name],'Lookup sheet'!A10,Easter[[Quantity ]]) -> 3
A11: Bold & Plain Milk Large | B11: Large | C11: Milk | D11: 110 | E11: =SUMIF(Easter[Product Name],'Lookup sheet'!A11,Easter[[Quantity ]]) -> 107
A12: Bold & Plain White Large | B12: Large | C12: White | D12: 110 | E12: =SUMIF(Easter[Product Name],'Lookup sheet'!A12,Easter[[Quantity ]]) -> 2
A13: Bunny Pop Dark | C13: Dark | D13: 40 | E13: =SUMIF(Easter[Product Name],'Lookup sheet'!A13,Easter[[Quantity ]]) -> 21
A14: Bunny Pop Milk | C14: Milk | D14: 40 | E14: =SUMIF(Easter[Product Name],'Lookup sheet'!A14,Easter[[Quantity ]]) -> 30
A15: Cookie And Dreams Large | B15: Large | C15: White | D15: 130 | E15: =SUMIF(Easter[Product Name],'Lookup sheet'!A15,Easter[[Quantity ]]) -> 12
A16: Cookie and Dreams Medium | B16: Medium | C16: White | D16: 60 | E16: =SUMIF(Easter[Product Name],'Lookup sheet'!A16,Easter[[Quantity ]]) -> 83
A17: Cookie and Dreams Mini | B17: Mini | C17: White | D17: 25 | E17: =SUMIF(Easter[Product Name],'Lookup sheet'!A17,Easter[[Quantity ]]) -> 89
A18: Mini Egglet Basket | D18: 150 | E18: =SUMIF(Easter[Product Name],'Lookup sheet'!A18,Easter[[Quantity ]]) -> 79
A19: Mocha Pop Large | B19: Large | C19: Milk | D19: 130 | E19: =SUMIF(Easter[Product Name],'Lookup sheet'!A19,Easter[[Quantity ]]) -> 18
A20: Mocha Pop Medium | B20: Medium | C20: Milk | D20: 55 | E20: =SUMIF(Easter[Product Name],'Lookup sheet'!A20,Easter[[Quantity ]]) -> 81
A21: Mocha Pop mini | B21: Mini | C21: Milk | D21: 25 | E21: =SUMIF(Easter[Product Name],'Lookup sheet'!A21,Easter[[Quantity ]]) -> 101
A22: Party Popper | D22: 100 | E22: =SUMIF(Easter[Product Name],'Lookup sheet'!A22,Easter[[Quantity ]]) -> 52
A23: Plain Dark Medium | B23: Medium | C23: Dark | D23: 50 | E23: =SUMIF(Easter[Product Name],'Lookup sheet'!A23,Easter[[Quantity ]]) -> 44
A24: Plain Dark Mini | B24: Mini | C24: Dark | D24: 20 | E24: =SUMIF(Easter[Product Name],'Lookup sheet'!A24,Easter[[Quantity ]]) -> 60
A25: Plain Milk Medium | B25: Medium | C25: Milk | D25: 50 | E25: =SUMIF(Easter[Product Name],'Lookup sheet'!A25,Easter[[Quantity ]]) -> 38
A26: Plain Milk Mini | B26: Mini | C26: Milk | D26: 20 | E26: =SUMIF(Easter[Product Name],'Lookup sheet'!A26,Easter[[Quantity ]]) -> 27
A27: Plain White Medium | B27: Medium | C27: White | D27: 50 | E27: =SUMIF(Easter[Product Name],'Lookup sheet'!A27,Easter[[Quantity ]]) -> 10
A28: Plain White Mini | B28: Mini | C28: White | D28: 20 | E28: =SUMIF(Easter[Product Name],'Lookup sheet'!A28,Easter[[Quantity ]]) -> 6
A29: Rum Drop Large | B29: Large | C29: Dark | D29: 130 | E29: =SUMIF(Easter[Product Name],'Lookup sheet'!A29,Easter[[Quantity ]]) -> 30
A30: Rum Drop Medium | B30: Medium | C30: Dark | D30: 55 | E30: =SUMIF(Easter[Product Name],'Lookup sheet'!A30,Easter[[Quantity ]]) -> 90
A31: Rum Drop Mini | B31: Mini | C31: Dark | D31: 25 | E31: =SUMIF(Easter[Product Name],'Lookup sheet'!A31,Easter[[Quantity ]]) -> 91

Sheet Payout Sheet
A1: TOTAL | D1: EXPENSE | G1: PAYOUT BALANCE
A2: Payment Recived | B2: Amount | D2: Name | E2: Amount Spent | G2: Name | H2: Amount Held | I2: (-)Expense | J2: Balance
A3: UPI Sarah | B3: =SUMIF('Order sheet'!$J$6:$J$352,"UPI Sarah",Easter[Total Payment]) -> 29625 | D3: Anna | E3: 3846 | G3: Anna | H3: =B4+B5 -> 57030 | I3: =H3-E3 -> 53184 | J3: =D8-I3 -> -22611
A4: UPI Anna | B4: =SUMIF('Order sheet'!$J$6:$J$352,"UPI Anna",Easter[Total Payment]) -> 41765 | D4: Sarah | E4: 21663 | G4: Sarah | H4: =B3 -> 29625 | I4: =H4-E4 -> 7962 | J4: =D8-I4 -> 22611
A5: Cash | B5: 15265 | D5: Total | E5: =SUM(E3:E4) -> 25509
A6: Pending | B6: =SUMIF('Order sheet'!$J$6:$J$352,"",Easter[Total Payment]) -> 205
A7: Total | B7: =SUM(B3:B5) -> 86655 | D7: Per Person Split
D8: =A10/2 -> 30573
A9: Net Profit
A10: =B7-E5 -> 61146
